<?xml version="1.0" ?>
<!-- =================================================================================== -->
<!-- |    This document was autogenerated by xacro from syscombase.xacro               | -->
<!-- |    EDITING THIS FILE BY HAND IS NOT RECOMMENDED                                 | -->
<!-- =================================================================================== -->
<robot name="box_robot" xmlns:xacro="http://ros.org/wiki/xacro">
  <!--base_height/2+torso_height/2 -->
  <!-- Define a number of dimensions using properties -->
  <!--property name="torso1_offset_x" value="0.185" />
   <property name="torso1_offset_y" value="0.16" />
   <property name="torso1_offset_z" value="0.15" /-->
  <!-- Define a number of dimensions using properties -->
  <!--property name="torso2_offset_x" value="-0.185" />
   <property name="torso2_offset_y" value="0.165" />
   <property name="torso2_offset_z" value="0.15" /-->
  <!-- Define a number of dimensions using properties -->
  <!--property name="torso3_offset_x" value="-0.185" />
   <property name="torso3_offset_y" value="-0.165" />
   <property name="torso3_offset_z" value="0.15" /-->
  <!-- Define a number of dimensions using properties -->
  <!--property name="torso4_offset_x" value="0.185" />
   <property name="torso4_offset_y" value="-0.165" />
   <property name="torso4_offset_z" value="0.15" /-->
  <!-- Put all the color definitions in a separate file -->
  <material name="Black">
    <color rgba="0.2 0.2 0.2 1.0"/>
  </material>
  <material name="TransparentBlack">
    <color rgba="0.2 0.2 0.2 0.8"/>
  </material>
  <material name="Orange">
    <color rgba="1.0  0.55 0.0 1.0"/>
  </material>
  <material name="Grey">
    <color rgba="0.7 0.7 0.7 1.0"/>
  </material>
  <material name="DarkGrey">
    <color rgba="0.3 0.3 0.3 1.0"/>
  </material>
  <material name="Red">
    <color rgba="0.8 0.0 0.0 1.0"/>
  </material>
  <material name="White">
    <color rgba="1.0 1.0 1.0 1.0"/>
  </material>
  <material name="OffWhite">
    <color rgba="0.8 0.8 0.8 1.0"/>
  </material>
  <material name="Blue">
    <color rgba="0.0 0.0 0.8 1.0"/>
  </material>
  <material name="Green">
    <color rgba="0.0 0.8 0.0 1.0"/>
  </material>
  <material name="TransparentGreen">
    <color rgba="0.0 0.8 0.0 0.5"/>
  </material>
  <material name="Yellow">
    <color rgba="1.0 1.0 0.0 1.0"/>
  </material>
  <material name="Gold">
    <color rgba="1.0 0.549 0.0 1.0"/>
  </material>
  <material name="Cyan">
    <color rgba="0.0 1.0 1.0 1.0"/>
  </material>
  <!-- laser-->
  <!--property name="laser_length" value="0.1" /> 
   <property name="laser_radius" value="0.05" /-->
  <!--define the base_footprint-->
  <link name="base_link">
    <visual>
      <origin rpy="0 0 0" xyz="0 0 0.025"/>
      <geometry>
        <box size="0.41 0.483 0.05"/>
      </geometry>
      <material name="DarkGrey"/>
    </visual>
  </link>
  <joint name="base_joint" type="fixed">
    <origin rpy="0 0 0" xyz="0 0 0.025"/>
    <parent link="base_link"/>
    <child link="base_link_f"/>
  </joint>
  <joint name="base_l_wheel_joint" type="continuous">
    <axis xyz="0 0 1"/>
    <limit effort="100" velocity="100"/>
    <safety_controller k_velocity="10"/>
    <origin rpy="1.57075 0 0" xyz="-0.18 0.2415 0"/>
    <parent link="base_link_f"/>
    <child link="base_l_wheel_link"/>
  </joint>
  <link name="base_l_wheel_link">
    <visual>
      <origin rpy="0 0 0" xyz="-0.01 0 0"/>
      <geometry>
        <cylinder length="0.076" radius="0.076"/>
      </geometry>
      <material name="Cyan"/>
    </visual>
  </link>
  <joint name="base_r_wheel_joint" type="continuous">
    <axis xyz="0 0 1"/>
    <limit effort="100" velocity="100"/>
    <safety_controller k_velocity="10"/>
    <origin rpy="-1.57075 0 0" xyz="-0.18 -0.2415 0"/>
    <parent link="base_link_f"/>
    <child link="base_r_wheel_link"/>
  </joint>
  <link name="base_r_wheel_link">
    <visual>
      <origin rpy="0 0 0" xyz="-0.01 0 0"/>
      <geometry>
        <cylinder length="0.076" radius="0.076"/>
      </geometry>
      <material name="Cyan"/>
    </visual>
  </link>
  <!-- Add the base and wheels-->
  <!--base name="base" color="Red"/-->
  <link name="base_link_f">
    <!--visual>
         <origin xyz="${origin_x} ${origin_y} ${origin_z + 0.27}" rpy="${angle_x} ${angle_y} ${angle_z}" />
           <geometry>
             <box size="${base_size_x} ${base_size_y - 0.133} ${base_size_z -0.04}" />
           </geometry>  
           <material name="${color}" />
       </visual>
         <collision>
           <origin xyz="${origin_x} ${origin_y} ${origin_z}" rpy="0 0 0" />
             <geometry>
               <box size="${base_size_x} ${wheel_offset_y*2 + wheel_length} ${base_size_z}" />
             </geometry>
         </collision-->
    <!-- define the balance xacro macro-->
    <!--visual>
         <origin xyz="${origin_x + 0.285} ${origin_y} ${origin_z + 0.095}" rpy="${angle_x} ${angle_y} ${angle_z}" />
           <geometry>
             <box size="${base_size_x - 0.29} ${base_size_y} ${base_size_z}" />
           </geometry>  
           <material name="${color}" />
       </visual>
         <collision>
           <origin xyz="${origin_x} ${origin_y} ${origin_z}" rpy="0 0 0" />
             <geometry>
               <box size="${base_size_x} ${wheel_offset_y*2 + wheel_length} ${base_size_z}" />
             </geometry>
         </collision-->
    <!--deifne the four cylinder xacro macro: first-->
    <visual>
      <origin rpy="0 0 0" xyz="0.185 0.165 0.145"/>
      <geometry>
        <cylinder length="0.25" radius="0.005"/>
      </geometry>
      <material name="Orange"/>
    </visual>
    <collision>
      <origin rpy="0 0 0" xyz="0 0 0"/>
      <geometry>
        <cylinder length="0.25" radius="0.005"/>
      </geometry>
    </collision>
    <!--deifne the four cylinder xacro macro: second-->
    <visual>
      <origin rpy="0 0 0" xyz="-0.185 0.165 0.145"/>
      <geometry>
        <cylinder length="0.25" radius="0.005"/>
      </geometry>
      <material name="Orange"/>
    </visual>
    <collision>
      <origin rpy="0 0 0" xyz="0 0 0"/>
      <geometry>
        <cylinder length="0.25" radius="0.005"/>
      </geometry>
    </collision>
    <!--deifne the four cylinder xacro macro: third-->
    <visual>
      <origin rpy="0 0 0" xyz="-0.185 -0.165 0.145"/>
      <geometry>
        <cylinder length="0.25" radius="0.005"/>
      </geometry>
      <material name="Orange"/>
    </visual>
    <collision>
      <origin rpy="0 0 0" xyz="0 0 0"/>
      <geometry>
        <cylinder length="0.25" radius="0.005"/>
      </geometry>
    </collision>
    <!--deifne the four cylinder xacro macro: fourth-->
    <visual>
      <origin rpy="0 0 0" xyz="0.185 -0.165 0.145"/>
      <geometry>
        <cylinder length="0.25" radius="0.005"/>
      </geometry>
      <material name="Orange"/>
    </visual>
    <collision>
      <origin rpy="0 0 0" xyz="0 0 0"/>
      <geometry>
        <cylinder length="0.25" radius="0.005"/>
      </geometry>
    </collision>
    <!--deifne the auxiliary wheel xacro macro: right-->
    <!--visual>
           <origin xyz="${origin_x + 0.2875} ${origin_y - 0.1915} ${origin_z}" rpy="${angle_x + PI/2} ${angle_y + PI/2} ${angle_z}"/>
             <geometry>
               <cylinder length="${wheel_length}" radius="${wheel_length}"/>
             </geometry>
             <material name="${color}" />
        </visual>
        <collision>
          <origin xyz="0 0 0" rpy="0 0 0"/>
            <geometry>
              <cylinder length="${wheel_length}" radius="${wheel_length}"/>
            </geometry>
        </collision-->
    <!--deifne the auxiliary wheel xacro macro: left-->
    <!--visual>
           <origin xyz="${origin_x + 0.2875} ${origin_y + 0.1915} ${origin_z}" rpy="${angle_x + PI/2} ${angle_y + PI/2} ${angle_z}"/>
             <geometry>
               <cylinder length="${wheel_length}" radius="${wheel_length}"/>
             </geometry>
             <material name="${color}" />
        </visual>
        <collision>
          <origin xyz="0 0 0" rpy="0 0 0"/>
            <geometry>
              <cylinder length="${wheel_length}" radius="${wheel_length}"/>
            </geometry>
        </collision-->
    <!--deifne the laser xacro macro>
        <visual>
           <origin xyz="${origin_x + 0.285} ${origin_y} ${origin_z + 0.158}" rpy="${angle_x} ${angle_y} ${angle_z}"/>
             <geometry>
               <cylinder length="${laser_length}" radius="${laser_radius}"/>
             </geometry>
             <material name="${color}" />
        </visual>
        <collision>
          <origin xyz="0 0 0" rpy="0 0 0"/>
            <geometry>
              <cylinder length="${laser_length}" radius="${laser_radius}"/>
            </geometry>
        </collision-->
    <!-- define the battery xacro macro-->
    <!--visual>
          <origin xyz="${origin_x - 0.08} ${origin_y} ${origin_z + 0.125}" rpy="${angle_x} ${angle_y} ${angle_z}" />
            <geometry>
              <box size="${base_size_x - 0.21} ${base_size_y - 0.18} ${base_size_z + 0.2}" />
            </geometry>  
            <material name="${color}" />
        </visual>
           <collision>
             <origin xyz="${origin_x} ${origin_y} ${origin_z}" rpy="0 0 0" />
               <geometry>
                 <box size="${base_size_x} ${wheel_offset_y*2 + wheel_length} ${base_size_z}" />
               </geometry>
           </collision-->
    <!-- define the decrease voltage xacro macro-->
    <!--visual>
          <origin xyz="${origin_x + 0.05} ${origin_y} ${origin_z + 0.125}" rpy="${angle_x} ${angle_y} ${angle_z}" />
            <geometry>
              <box size="${base_size_x - 0.36} ${base_size_y - 0.24} ${base_size_z + 0.15}" />
            </geometry>  
            <material name="${color}" />
        </visual>
           <collision>
             <origin xyz="${origin_x} ${origin_y} ${origin_z}" rpy="0 0 0" />
               <geometry>
                 <box size="${base_size_x} ${wheel_offset_y*2 + wheel_length} ${base_size_z}" />
               </geometry>
           </collision-->
  </link>
  <!--Add the torso1-->
  <!--torso1 name="torso1" parent="base" color="Gold" >
     <origin xyz="${torso1_offset_x} ${torso1_offset_y} ${torso1_offset_z}" rpy="0 0 0" />
   </torso1-->
  <!--Add the torso2-->
  <!--torso2 name="torso2" parent="base" color="Gold" >
     <origin xyz="${torso2_offset_x} ${torso2_offset_y} ${torso2_offset_z}" rpy="0 0 0" />
   </torso2-->
  <!--Add the torso3-->
  <!--torso3 name="torso3" parent="base" color="Gold" >
     <origin xyz="${torso3_offset_x} ${torso3_offset_y} ${torso3_offset_z}" rpy="0 0 0" />
   </torso3-->
  <!--Add the torso4-->
  <!--torso4 name="torso4" parent="base" color="Gold" >
     <origin xyz="${torso4_offset_x} ${torso4_offset_y} ${torso4_offset_z}" rpy="0 0 0" />
   </torso4-->
  <joint name="base_laser_joint" type="fixed">
    <origin rpy="0 0 0" xyz="0.285 0 0.158"/>
    <parent link="base_link_f"/>
    <child link="laser_link"/>
  </joint>
  <link name="laser_link">
    <visual>
      <origin rpy="0 0 0" xyz="0 0 0"/>
      <geometry>
        <cylinder length="0.1" radius="0.05"/>
      </geometry>
      <material name="Yellow"/>
    </visual>
    <collision>
      <origin rpy="0 0 0" xyz="0 0 0"/>
      <geometry>
        <cylinder length="0.1" radius="0.05"/>
      </geometry>
    </collision>
  </link>
  <joint name="base_balance_joint" type="fixed">
    <origin rpy="0 0 0" xyz="0.285 0 0.095"/>
    <parent link="base_link_f"/>
    <child link="balance_link"/>
  </joint>
  <link name="balance_link">
    <visual>
      <origin rpy="0 0 0" xyz="0 0 0"/>
      <geometry>
        <box size="0.12 0.48 0.05"/>
      </geometry>
      <material name="Red"/>
    </visual>
    <collision>
      <origin rpy="0 0 0" xyz="0 0 0"/>
      <geometry>
        <box size="0.12 0.48 0.05"/>
      </geometry>
    </collision>
  </link>
  <joint name="base_auxiliary_wheel_right_joint" type="fixed">
    <origin rpy="1.57075 1.57075 0" xyz="0.2875 -0.1915 0"/>
    <parent link="base_link_f"/>
    <child link="auxiliary_wheel_right_link"/>
  </joint>
  <link name="auxiliary_wheel_right_link">
    <visual>
      <origin rpy="0 0 0" xyz="0 0 0"/>
      <geometry>
        <cylinder length="0.076" radius="0.076"/>
      </geometry>
      <material name="Green"/>
    </visual>
    <collision>
      <origin rpy="0 0 0" xyz="0 0 0"/>
      <geometry>
        <cylinder length="0.076" radius="0.076"/>
      </geometry>
    </collision>
  </link>
  <joint name="base_auxiliary_wheel_left_joint" type="fixed">
    <origin rpy="1.57075 1.57075 0" xyz="0.2875 0.1915 0"/>
    <parent link="base_link_f"/>
    <child link="auxiliary_wheel_left_link"/>
  </joint>
  <link name="auxiliary_wheel_left_link">
    <visual>
      <origin rpy="0 0 0" xyz="0 0 0"/>
      <geometry>
        <cylinder length="0.076" radius="0.076"/>
      </geometry>
      <material name="Green"/>
    </visual>
    <collision>
      <origin rpy="0 0 0" xyz="0 0 0"/>
      <geometry>
        <cylinder length="0.076" radius="0.076"/>
      </geometry>
    </collision>
  </link>
  <joint name="base_decrease_voltage_joint" type="fixed">
    <origin rpy="0 0 0" xyz="0.05 0 0.125"/>
    <parent link="base_link_f"/>
    <child link="decrease_voltage_link"/>
  </joint>
  <link name="decrease_voltage_link">
    <visual>
      <origin rpy="0 0 0" xyz="0 0 0"/>
      <geometry>
        <box size="0.05 0.25 0.2"/>
      </geometry>
      <material name="White"/>
    </visual>
    <collision>
      <origin rpy="0 0 0" xyz="0 0 0"/>
      <geometry>
        <box size="0.05 0.25 0.2"/>
      </geometry>
    </collision>
  </link>
  <joint name="base_battery_joint" type="fixed">
    <origin rpy="0 0 0" xyz="-0.1 0 0.125"/>
    <parent link="base_link_f"/>
    <child link="battery_link"/>
  </joint>
  <link name="battery_link">
    <visual>
      <origin rpy="0 0 0" xyz="0 0 0"/>
      <geometry>
        <box size="0.2 0.3 0.25"/>
      </geometry>
      <material name="Blue"/>
    </visual>
    <collision>
      <origin rpy="0 0 0" xyz="0 0 0"/>
      <geometry>
        <box size="0.2 0.3 0.25"/>
      </geometry>
    </collision>
  </link>
  <joint name="base_up_layer_joint" type="fixed">
    <origin rpy="0 0 0" xyz="0 0 0.27"/>
    <parent link="base_link_f"/>
    <child link="up_layer_link"/>
  </joint>
  <link name="up_layer_link">
    <visual>
      <origin rpy="0 0 0" xyz="0 0 0"/>
      <geometry>
        <box size="0.41 0.35 0.01"/>
      </geometry>
      <material name="TransparentBlack"/>
    </visual>
    <collision>
      <origin rpy="0 0 0" xyz="0 0 0"/>
      <geometry>
        <box size="0.41 0.35 0.01"/>
      </geometry>
    </collision>
  </link>
</robot>

